Workbook
Name Slicer_manager: #N/A
Name Slicer_regional_office: #N/A

Sheet Graphs
R5: KPI
R6: Total Opporunies : 1985
R7: Won Opportunties :1196
R8: Lost Opportunties : 789
R9: Win Rate : 60%
R10: Best Sales : Darcell Schedel
R11: Best Quarter : Q3
X16: ٍ

Sheet pivot table 
A1: deal_stage | B1: Won
B3: Column Labels
B4: 2017 | F4: 2017 Total | G4: Grand Total
B5: Qtr4 | C5: Qtr3 | D5: Qtr2 | E5: Qtr1
A6: Count of opportunity_id | B6: 1196 | C6: 1257 | D6: 1254 | E6: 531 | F6: 4238 | G6: 4238
A17: Count of opportunity_id | B17: Column Labels
B18: 2017 | F18: 2017 Total | G18: Grand Total
A19: Row Labels | B19: Qtr4 | C19: Qtr3 | D19: Qtr2 | E19: Qtr1
A20: Lost | B20: 0.39748111 | C20: 0.38593063 | D20: 0.38287402 | E20: 0.17928903 | F20: 0.36849948 | G20: 0.36849948
A21: Won | B21: 0.60251889 | C21: 0.61406937 | D21: 0.61712598 | E21: 0.82071097 | F21: 0.63150052 | G21: 0.63150052
A22: Grand Total | B22: 1 | C22: 1 | D22: 1 | E22: 1 | F22: 1 | G22: 1
A30: deal_stage | B30: Won
A32: Count of opportunity_id | B32: Column Labels
B33: 2017 | F33: 2017 Total | G33: Grand Total
A34: Row Labels | B34: Qtr4 | C34: Qtr3 | D34: Qtr2 | E34: Qtr1
A35: Donn Cantrell | B35: 37 | C35: 58 | D35: 44 | E35: 19 | F35: 158 | G35: 158
A36: Cassey Cress | B36: 39 | C36: 53 | D36: 48 | E36: 23 | F36: 163 | G36: 163
A37: Reed Clapper | B37: 38 | C37: 49 | D37: 49 | E37: 19 | F37: 155 | G37: 155
A38: Corliss Cosme | B38: 43 | C38: 48 | D38: 36 | E38: 23 | F38: 150 | G38: 150
A39: Violet Mclelland | B39: 35 | C39: 36 | D39: 34 | E39: 17 | F39: 122 | G39: 122
A40: Boris Faz | B40: 34 | C40: 31 | D40: 29 | E40: 7 | F40: 101 | G40: 101
A41: Daniell Hammack | B41: 27 | C41: 29 | D41: 47 | E41: 11 | F41: 114 | G41: 114
A42: Garret Kinder | B42: 16 | C42: 24 | D42: 22 | E42: 13 | F42: 75 | G42: 75
A43: Rosie Papadopoulos | B43: 21 | C43: 23 | D43: 26 | E43: 8 | F43: 78 | G43: 78
A44: Wilburn Farren | B44: 22 | C44: 16 | D44: 14 | E44: 3 | F44: 55 | G44: 55
A45: Grand Total | B45: 312 | C45: 367 | D45: 349 | E45: 143 | F45: 1171 | G45: 1171

Sheet sales_pipeline
A1: opportunity_id | B1: sales_agent | C1: manager | D1: regional_office | E1: product | F1: account | G1: deal_stage | H1: engage_date | I1: close_date | J1: close_value
A2: 1C1I7A6R | B2: Moses Frase | C2: =_xlfn.XLOOKUP(B2, [1]sales_teams!$A$2:$A$100, [1]sales_teams!$B$2:$B$100) -> Dustin Brinkmann | D2: =_xlfn.XLOOKUP($B2,sales_teams!$A$2:$A$36,sales_teams!C$2:C$36) -> Central | E2: GTX Plus Basic | F2: Cancity | G2: Won | H2: 42663 | I2: 42795 | J2: 1054
A3: Z063OYW0 | B3: Darcel Schlecht | C3: =_xlfn.XLOOKUP(B3, [1]sales_teams!$A$2:$A$100, [1]sales_teams!$B$2:$B$100) -> Melvin Marxen | D3: =_xlfn.XLOOKUP($B3,sales_teams!$A$2:$A$36,sales_teams!C$2:C$36) -> Central | E3: GTXPro | F3: Isdom | G3: Won | H3: 42668 | I3: 42805 | J3: 4514
A4: EC4QE1BX | B4: Darcel Schlecht | C4: =_xlfn.XLOOKUP(B4, [1]sales_teams!$A$2:$A$100, [1]sales_teams!$B$2:$B$100) -> Melvin Marxen | D4: =_xlfn.XLOOKUP($B4,sales_teams!$A$2:$A$36,sales_teams!C$2:C$36) -> Central | E4: MG Special | F4: Cancity | G4: Won | H4: 42668 | I4: 42801 | J4: 50
A5: MV1LWRNH | B5: Moses Frase | C5: =_xlfn.XLOOKUP(B5, [1]sales_teams!$A$2:$A$100, [1]sales_teams!$B$2:$B$100) -> Dustin Brinkmann | D5: =_xlfn.XLOOKUP($B5,sales_teams!$A$2:$A$36,sales_teams!C$2:C$36) -> Central | E5: GTX Basic | F5: Codehow | G5: Won | H5: 42668 | I5: 42803 | J5: 588
A6: PE84CX4O | B6: Zane Levy | C6: =_xlfn.XLOOKUP(B6, [1]sales_teams!$A$2:$A$100, [1]sales_teams!$B$2:$B$100) -> Summer Sewald | D6: =_xlfn.XLOOKUP($B6,sales_teams!$A$2:$A$36,sales_teams!C$2:C$36) -> West | E6: GTX Basic | F6: Hatfan | G6: Won | H6: 42668 | I6: 42796 | J6: 517
A7: ZNBS69V1 | B7: Anna Snelling | C7: =_xlfn.XLOOKUP(B7, [1]sales_teams!$A$2:$A$100, [1]sales_teams!$B$2:$B$100) -> Dustin Brinkmann | D7: =_xlfn.XLOOKUP($B7,sales_teams!$A$2:$A$36,sales_teams!C$2:C$36) -> Central | E7: MG Special | F7: Ron-tech | G7: Won | H7: 42672 | I7: 42795 | J7: 49
A8: 9ME3374G | B8: Vicki Laflamme | C8: =_xlfn.XLOOKUP(B8, [1]sales_teams!$A$2:$A$100, [1]sales_teams!$B$2:$B$100) -> Celia Rouche | D8: =_xlfn.XLOOKUP($B8,sales_teams!$A$2:$A$36,sales_teams!C$2:C$36) -> West | E8: MG Special | F8: J-Texon | G8: Won | H8: 42673 | I8: 42796 | J8: 57
A9: 7GN8Q4LL | B9: Markita Hansen | C9: =_xlfn.XLOOKUP(B9, [1]sales_teams!$A$2:$A$100, [1]sales_teams!$B$2:$B$100) -> Celia Rouche | D9: =_xlfn.XLOOKUP($B9,sales_teams!$A$2:$A$36,sales_teams!C$2:C$36) -> West | E9: GTX Basic | F9: Cheers | G9: Won | H9: 42675 | I9: 42801 | J9: 601
A10: OLK9LKZB | B10: Niesha Huffines | C10: =_xlfn.XLOOKUP(B10, [1]sales_teams!$A$2:$A$100, [1]sales_teams!$B$2:$B$100) -> Melvin Marxen | D10: =_xlfn.XLOOKUP($B10,sales_teams!$A$2:$A$36,sales_teams!C$2:C$36) -> Central | E10: GTX Plus Basic | F10: Zumgoity | G10: Won | H10: 42675 | I10: 42797 | J10: 1026
A11: HAXMC4IX | B11: James Ascencio | C11: =_xlfn.XLOOKUP(B11, [1]sales_teams!$A$2:$A$100, [1]sales_teams!$B$2:$B$100) -> Summer Sewald | D11: =_xlfn.XLOOKUP($B11,sales_teams!$A$2:$A$36,sales_teams!C$2:C$36) -> West | E11: MG Advanced | G11: Engaging | H11: 42677
A12: NL3JZH1Z | B12: Anna Snelling | C12: =_xlfn.XLOOKUP(B12, [1]sales_teams!$A$2:$A$100, [1]sales_teams!$B$2:$B$100) -> Dustin Brinkmann | D12: =_xlfn.XLOOKUP($B12,sales_teams!$A$2:$A$36,sales_teams!C$2:C$36) -> Central | E12: MG Special | F12: Bioholding | G12: Won | H12: 42678 | I12: 42804 | J12: 53
A13: KWVA7VR1 | B13: Gladys Colclough | C13: =_xlfn.XLOOKUP(B13, [1]sales_teams!$A$2:$A$100, [1]sales_teams!$B$2:$B$100) -> Melvin Marxen | D13: =_xlfn.XLOOKUP($B13,sales_teams!$A$2:$A$36,sales_teams!C$2:C$36) -> Central | E13: GTXPro | F13: Genco Pura Olive Oil Company | G13: Lost | H13: 42678 | I13: 42812 | J13: 0
A14: S8DX3XOU | B14: James Ascencio | C14: =_xlfn.XLOOKUP(B14, [1]sales_teams!$A$2:$A$100, [1]sales_teams!$B$2:$B$100) -> Summer Sewald | D14: =_xlfn.XLOOKUP($B14,sales_teams!$A$2:$A$36,sales_teams!C$2:C$36) -> West | E14: GTX Plus Pro | F14: Sunnamplex | G14: Won | H14: 42678 | I14: 42804 | J14: 5169
A15: ENB2XD8G | B15: Maureen Marcano | C15: =_xlfn.XLOOKUP(B15, [1]sales_teams!$A$2:$A$100, [1]sales_teams!$B$2:$B$100) -> Summer Sewald | D15: =_xlfn.XLOOKUP($B15,sales_teams!$A$2:$A$36,sales_teams!C$2:C$36) -> West | E15: GTX Plus Pro | F15: Sonron | G15: Won | H15: 42678 | I15: 42800 | J15: 4631
A16: 09YE9QOV | B16: Hayden Neloms | C16: =_xlfn.XLOOKUP(B16, [1]sales_teams!$A$2:$A$100, [1]sales_teams!$B$2:$B$100) -> Celia Rouche | D16: =_xlfn.XLOOKUP($B16,sales_teams!$A$2:$A$36,sales_teams!C$2:C$36) -> West | E16: MG Advanced | F16: Finjob | G16: Won | H16: 42679 | I16: 42805 | J16: 3393
A17: 3F5MZNEH | B17: Rosalina Dieter | C17: =_xlfn.XLOOKUP(B17, [1]sales_teams!$A$2:$A$100, [1]sales_teams!$B$2:$B$100) -> Celia Rouche | D17: =_xlfn.XLOOKUP($B17,sales_teams!$A$2:$A$36,sales_teams!C$2:C$36) -> West | E17: MG Special | F17: Sonron | G17: Lost | H17: 42679 | I17: 42797 | J17: 0
A18: M6WEJXC0 | B18: Rosalina Dieter | C18: =_xlfn.XLOOKUP(B18, [1]sales_teams!$A$2:$A$100, [1]sales_teams!$B$2:$B$100) -> Celia Rouche | D18: =_xlfn.XLOOKUP($B18,sales_teams!$A$2:$A$36,sales_teams!C$2:C$36) -> West | E18: MG Advanced | F18: Scotfind | G18: Won | H18: 42679 | I18: 42800 | J18: 3284
A19: 6PTR7VBR | B19: Versie Hillebrand | C19: =_xlfn.XLOOKUP(B19, [1]sales_teams!$A$2:$A$100, [1]sales_teams!$B$2:$B$100) -> Dustin Brinkmann | D19: =_xlfn.XLOOKUP($B19,sales_teams!$A$2:$A$36,sales_teams!C$2:C$36) -> Central | E19: MG Special | F19: Treequote | G19: Won | H19: 42680 | I19: 42799 | J19: 61
A20: 902REDPA | B20: Daniell Hammack | C20: =_xlfn.XLOOKUP(B20, [1]sales_teams!$A$2:$A$100, [1]sales_teams!$B$2:$B$100) -> Rocco Neubert | D20: =_xlfn.XLOOKUP($B20,sales_teams!$A$2:$A$36,sales_teams!C$2:C$36) -> East | E20: GTXPro | F20: Xx-zobam | G20: Lost | H20: 42681 | I20: 42803 | J20: 0
A21: 5J9CMGDV | B21: Elease Gluck | C21: =_xlfn.XLOOKUP(B21, [1]sales_teams!$A$2:$A$100, [1]sales_teams!$B$2:$B$100) -> Celia Rouche | D21: =_xlfn.XLOOKUP($B21,sales_teams!$A$2:$A$36,sales_teams!C$2:C$36) -> West | E21: MG Special | F21: Rantouch | G21: Won | H21: 42681 | I21: 42802 | J21: 46
A22: JJXRR8R6 | B22: James Ascencio | C22: =_xlfn.XLOOKUP(B22, [1]sales_teams!$A$2:$A$100, [1]sales_teams!$B$2:$B$100) -> Summer Sewald | D22: =_xlfn.XLOOKUP($B22,sales_teams!$A$2:$A$36,sales_teams!C$2:C$36) -> West | E22: GTX Plus Pro | F22: Fasehatice | G22: Lost | H22: 42681 | I22: 42811 | J22: 0
A23: WF4HA5NW | B23: Moses Frase | C23: =_xlfn.XLOOKUP(B23, [1]sales_teams!$A$2:$A$100, [1]sales_teams!$B$2:$B$100) -> Dustin Brinkmann | D23: =_xlfn.XLOOKUP($B23,sales_teams!$A$2:$A$36,sales_teams!C$2:C$36) -> Central | E23: MG Special | F23: Ron-tech | G23: Won | H23: 42681 | I23: 42812 | J23: 50
... A26: SBCR987L | B26: Kami Bicknell | C26: =_xlfn.XLOOKUP(B26, [1]sales_teams!$A$2:$A$100, [1]sales_teams!$B$2:$B$100) -> Summer Sewald | D26: =_xlfn.XLOOKUP($B26,sales_teams!$A$2:$A$36,sales_teams!C$2:C$36) -> West | E26: GTX Basic | F26: Zoomit | G26: Won | H26: 42684 | I26: 42817 | J26: 590
A27: UP409DSB | B27: Maureen Marcano | C27: =_xlfn.XLOOKUP(B27, [1]sales_teams!$A$2:$A$100, [1]sales_teams!$B$2:$B$100) -> Summer Sewald | D27: =_xlfn.XLOOKUP($B27,sales_teams!$A$2:$A$36,sales_teams!C$2:C$36) -> West | E27: MG Advanced | F27: Ganjaflex | G27: Engaging | H27: 42684
A28: JSD4APT2 | B28: Versie Hillebrand | C28: =_xlfn.XLOOKUP(B28, [1]sales_teams!$A$2:$A$100, [1]sales_teams!$B$2:$B$100) -> Dustin Brinkmann | D28: =_xlfn.XLOOKUP($B28,sales_teams!$A$2:$A$36,sales_teams!C$2:C$36) -> Central | E28: MG Special | F28: Bioholding | G28: Won | H28: 42684 | I28: 42806 | J28: 61
A29: AO9Z2D17 | B29: Violet Mclelland | C29: =_xlfn.XLOOKUP(B29, [1]sales_teams!$A$2:$A$100, [1]sales_teams!$B$2:$B$100) -> Cara Losch | D29: =_xlfn.XLOOKUP($B29,sales_teams!$A$2:$A$36,sales_teams!C$2:C$36) -> East | E29: GTX Plus Pro | F29: Xx-zobam | G29: Lost | H29: 42684 | I29: 42805 | J29: 0
A30: 5M58DTJK | B30: Elease Gluck | C30: =_xlfn.XLOOKUP(B30, [1]sales_teams!$A$2:$A$100, [1]sales_teams!$B$2:$B$100) -> Celia Rouche | D30: =_xlfn.XLOOKUP($B30,sales_teams!$A$2:$A$36,sales_teams!C$2:C$36) -> West | E30: MG Special | F30: Cheers | G30: Won | H30: 42685 | I30: 42799 | J30: 58
A31: KNY1OSAB | B31: Maureen Marcano | C31: =_xlfn.XLOOKUP(B31, [1]sales_teams!$A$2:$A$100, [1]sales_teams!$B$2:$B$100) -> Summer Sewald | D31: =_xlfn.XLOOKUP($B31,sales_teams!$A$2:$A$36,sales_teams!C$2:C$36) -> West | E31: GTXPro | F31: Labdrill | G31: Won | H31: 42685 | I31: 42808 | J31: 4899
A32: EAZDUUM9 | B32: Rosie Papadopoulos | C32: =_xlfn.XLOOKUP(B32, [1]sales_teams!$A$2:$A$100, [1]sales_teams!$B$2:$B$100) -> Cara Losch | D32: =_xlfn.XLOOKUP($B32,sales_teams!$A$2:$A$36,sales_teams!C$2:C$36) -> East | E32: MG Advanced | F32: Zotware | G32: Lost | H32: 42685 | I32: 42795 | J32: 0
A33: 2STUSOFE | B33: Versie Hillebrand | C33: =_xlfn.XLOOKUP(B33, [1]sales_teams!$A$2:$A$100, [1]sales_teams!$B$2:$B$100) -> Dustin Brinkmann | D33: =_xlfn.XLOOKUP($B33,sales_teams!$A$2:$A$36,sales_teams!C$2:C$36) -> Central | E33: MG Special | F33: dambase | G33: Won | H33: 42685 | I33: 42797 | J33: 67
A34: JYKM0B00 | B34: James Ascencio | C34: =_xlfn.XLOOKUP(B34, [1]sales_teams!$A$2:$A$100, [1]sales_teams!$B$2:$B$100) -> Summer Sewald | D34: =_xlfn.XLOOKUP($B34,sales_teams!$A$2:$A$36,sales_teams!C$2:C$36) -> West | E34: GTXPro | F34: Xx-holding | G34: Won | H34: 42686 | I34: 42800 | J34: 4338
A35: KU28360J | B35: Kary Hendrixson | C35: =_xlfn.XLOOKUP(B35, [1]sales_teams!$A$2:$A$100, [1]sales_teams!$B$2:$B$100) -> Summer Sewald | D35: =_xlfn.XLOOKUP($B35,sales_teams!$A$2:$A$36,sales_teams!C$2:C$36) -> West | E35: GTX Basic | F35: Fasehatice | G35: Won | H35: 42686 | I35: 42813 | J35: 578
A36: N4SD17JR | B36: Reed Clapper | C36: =_xlfn.XLOOKUP(B36, [1]sales_teams!$A$2:$A$100, [1]sales_teams!$B$2:$B$100) -> Rocco Neubert | D36: =_xlfn.XLOOKUP($B36,sales_teams!$A$2:$A$36,sales_teams!C$2:C$36) -> East | E36: GTX Basic | F36: Acme Corporation | G36: Won | H36: 42686 | I36: 42795 | J36: 556
A37: E67P9Y3Q | B37: Rosalina Dieter | C37: =_xlfn.XLOOKUP(B37, [1]sales_teams!$A$2:$A$100, [1]sales_teams!$B$2:$B$100) -> Celia Rouche | D37: =_xlfn.XLOOKUP($B37,sales_teams!$A$2:$A$36,sales_teams!C$2:C$36) -> West | E37: GTX Basic | F37: Green-Plus | G37: Won | H37: 42686 | I37: 42797 | J37: 635
A38: AT3MMVIS | B38: Wilburn Farren | C38: =_xlfn.XLOOKUP(B38, [1]sales_teams!$A$2:$A$100, [1]sales_teams!$B$2:$B$100) -> Cara Losch | D38: =_xlfn.XLOOKUP($B38,sales_teams!$A$2:$A$36,sales_teams!C$2:C$36) -> East | E38: MG Advanced | F38: The New York Inquirer | G38: Won | H38: 42686 | I38: 42801 | J38: 3045
A39: REJ11LRY | B39: Garret Kinder | C39: =_xlfn.XLOOKUP(B39, [1]sales_teams!$A$2:$A$100, [1]sales_teams!$B$2:$B$100) -> Cara Losch | D39: =_xlfn.XLOOKUP($B39,sales_teams!$A$2:$A$36,sales_teams!C$2:C$36) -> East | E39: GTX Plus Basic | F39: Mathtouch | G39: Won | H39: 42687 | I39: 42808 | J39: 1233
... A43: CZVN09WN | B43: Darcel Schlecht | C43: =_xlfn.XLOOKUP(B43, [1]sales_teams!$A$2:$A$100, [1]sales_teams!$B$2:$B$100) -> Melvin Marxen | D43: =_xlfn.XLOOKUP($B43,sales_teams!$A$2:$A$36,sales_teams!C$2:C$36) -> Central | E43: GTX Plus Basic | F43: Konmatfix | G43: Won | H43: 42688 | I43: 42814 | J43: 1170
A44: EG7OFLFR | B44: Kami Bicknell | C44: =_xlfn.XLOOKUP(B44, [1]sales_teams!$A$2:$A$100, [1]sales_teams!$B$2:$B$100) -> Summer Sewald | D44: =_xlfn.XLOOKUP($B44,sales_teams!$A$2:$A$36,sales_teams!C$2:C$36) -> West | E44: GTX Basic | G44: Engaging | H44: 42688
A45: 30UQWUKB | B45: Marty Freudenburg | C45: =_xlfn.XLOOKUP(B45, [1]sales_teams!$A$2:$A$100, [1]sales_teams!$B$2:$B$100) -> Melvin Marxen | D45: =_xlfn.XLOOKUP($B45,sales_teams!$A$2:$A$36,sales_teams!C$2:C$36) -> Central | E45: GTX Plus Basic | F45: Genco Pura Olive Oil Company | G45: Won | H45: 42689 | I45: 42814 | J45: 1162
...

Sheet sales_teams
A1: sales_agent | B1: manager | C1: regional_office
A2: Anna Snelling | B2: Dustin Brinkmann | C2: Central
A3: Cecily Lampkin | B3: Dustin Brinkmann | C3: Central
A4: Versie Hillebrand | B4: Dustin Brinkmann | C4: Central
A5: Lajuana Vencill | B5: Dustin Brinkmann | C5: Central
A6: Moses Frase | B6: Dustin Brinkmann | C6: Central
A7: Jonathan Berthelot | B7: Melvin Marxen | C7: Central
A8: Marty Freudenburg | B8: Melvin Marxen | C8: Central
A9: Gladys Colclough | B9: Melvin Marxen | C9: Central
A10: Niesha Huffines | B10: Melvin Marxen | C10: Central
A11: Darcel Schlecht | B11: Melvin Marxen | C11: Central
A12: Mei-Mei Johns | B12: Melvin Marxen | C12: Central
... A36: Carl Lin | B36: Summer Sewald | C36: West
